Workbook

Sheet Como ler
A1: Mapa de criadores · Itajaí, Balneário Camboriú, Camboriú e Itapema
A2: Coleta: 27/09/2026, Instagram, perfis públicos, via Apify (hashtags de cidade e nicho, busca por nome, menções e marcações nos posts).
A3: Métricas calculadas sobre os últimos ~12 posts públicos de cada perfil (posts fixados ignorados).
A5: Colunas
A6: Engajamento: mediana de (curtidas + comentários) por post ÷ seguidores. Mediana evita que um post viral distorça.
A7: Engaj. de referência: valor típico para a faixa de seguidores (tabela abaixo). "Engaj. vs referência" 1,00 = na média; 2,00 = o dobro.
A8: Views/seguidores: mediana de visualizações dos reels ÷ seguidores. Acima de 0,5 significa que os vídeos saem da bolha.
A9: Posts/semana e Último post: cadência e se a conta está ativa. Dias sem postar contam a partir da data de coleta.
A10: Publis (de 12): posts marcados como parceria paga ou com #publi/#publicidade. Marcas em publis: @ das marcas marcadas nesses posts.
A11: Nichos: detectados na bio (peso maior) e nas legendas/hashtags. Um criador pode ter até 4 nichos. Nicho principal = o mais forte.
A12: Como confirmei a cidade: "bio" = a pessoa escreve a cidade na bio; "N post(s) marcados" = posts com localização na cidade.
A13: Canal de contato: só indica o canal que a pessoa divulga (e-mail, WhatsApp, direct). Os dados em si não foram copiados.
... A18: Engajamento de referência por faixa
A19: Faixa | B19: Engajamento típico
A20: Nano (1k–3k) | B20: 0.04
A21: Micro (3k–30k) | B21: 0.025
A22: Média (30k–100k) | B22: 0.015
A23: Macro (100k–500k) | B23: 0.01
A24: Mega (500k+) | B24: 0.007
A25: Fonte: médias de mercado para Instagram (benchmarks públicos de 2024–2026); use como régua, não como regra.
A27: Data da coleta | B27: 46292

Sheet Resumo
A1: Resumo por cidade (cidade principal)
A3: Cidade | B3: Total | C3: Nano (1k–3k) | D3: Micro (3k–30k) | E3: Média (30k–100k) | F3: Macro (100k–500k) | G3: Mega (500k+) | H3: Mulher | I3: Homem | J3: Criador(a) | K3: Especialista | L3: Página local | M3: Fit alta | N3: Score médio
A4: Itajaí | B4: =COUNTIF('Base completa'!$A$2:$A$183,$A4) -> 58 | C4: =COUNTIFS('Base completa'!$A$2:$A$183,$A4,'Base completa'!$H$2:$H$183,"Nano (1k–3k)") -> 12 | D4: =COUNTIFS('Base completa'!$A$2:$A$183,$A4,'Base completa'!$H$2:$H$183,"Micro (3k–30k)") -> 34 | E4: =COUNTIFS('Base completa'!$A$2:$A$183,$A4,'Base completa'!$H$2:$H$183,"Média (30k–100k)") -> 9 | F4: =COUNTIFS('Base completa'!$A$2:$A$183,$A4,'Base completa'!$H$2:$H$183,"Macro (100k–500k)") -> 2 | G4: =COUNTIFS('Base completa'!$A$2:$A$183,$A4,'Base completa'!$H$2:$H$183,"Mega (500k+)") -> 1 | H4: =COUNTIFS('Base completa'!$A$2:$A$183,$A4,'Base completa'!$F$2:$F$183,"Mulher") -> 38 | I4: =COUNTIFS('Base completa'!$A$2:$A$183,$A4,'Base completa'!$F$2:$F$183,"Homem") -> 15 | J4: =COUNTIFS('Base completa'!$A$2:$A$183,$A4,'Base completa'!$E$2:$E$183,"Criador(a)") -> 35 | K4: =COUNTIFS('Base completa'!$A$2:$A$183,$A4,'Base completa'!$E$2:$E$183,"Especialista que cria conteúdo") -> 19 | L4: =COUNTIFS('Base completa'!$A$2:$A$183,$A4,'Base completa'!$E$2:$E$183,"Página local / guia") -> 4 | M4: =COUNTIFS('Base completa'!$A$2:$A$183,$A4,'Base completa'!$X$2:$X$183,"Alta") -> 28 | N4: =IFERROR(ROUND(AVERAGEIF('Base completa'!$A$2:$A$183,$A4,'Base completa'!$Y$2:$Y$183),0),"") -> 49
A5: Balneário Camboriú | B5: =COUNTIF('Base completa'!$A$2:$A$183,$A5) -> 81 | C5: =COUNTIFS('Base completa'!$A$2:$A$183,$A5,'Base completa'!$H$2:$H$183,"Nano (1k–3k)") -> 16 | D5: =COUNTIFS('Base completa'!$A$2:$A$183,$A5,'Base completa'!$H$2:$H$183,"Micro (3k–30k)") -> 42 | E5: =COUNTIFS('Base completa'!$A$2:$A$183,$A5,'Base completa'!$H$2:$H$183,"Média (30k–100k)") -> 13 | F5: =COUNTIFS('Base completa'!$A$2:$A$183,$A5,'Base completa'!$H$2:$H$183,"Macro (100k–500k)") -> 8 | G5: =COUNTIFS('Base completa'!$A$2:$A$183,$A5,'Base completa'!$H$2:$H$183,"Mega (500k+)") -> 2 | H5: =COUNTIFS('Base completa'!$A$2:$A$183,$A5,'Base completa'!$F$2:$F$183,"Mulher") -> 48 | I5: =COUNTIFS('Base completa'!$A$2:$A$183,$A5,'Base completa'!$F$2:$F$183,"Homem") -> 16 | J5: =COUNTIFS('Base completa'!$A$2:$A$183,$A5,'Base completa'!$E$2:$E$183,"Criador(a)") -> 33 | K5: =COUNTIFS('Base completa'!$A$2:$A$183,$A5,'Base completa'!$E$2:$E$183,"Especialista que cria conteúdo") -> 34 | L5: =COUNTIFS('Base completa'!$A$2:$A$183,$A5,'Base completa'!$E$2:$E$183,"Página local / guia") -> 14 | M5: =COUNTIFS('Base completa'!$A$2:$A$183,$A5,'Base completa'!$X$2:$X$183,"Alta") -> 24 | N5: =IFERROR(ROUND(AVERAGEIF('Base completa'!$A$2:$A$183,$A5,'Base completa'!$Y$2:$Y$183),0),"") -> 44
A6: Camboriú | B6: =COUNTIF('Base completa'!$A$2:$A$183,$A6) -> 9 | C6: =COUNTIFS('Base completa'!$A$2:$A$183,$A6,'Base completa'!$H$2:$H$183,"Nano (1k–3k)") -> 1 | D6: =COUNTIFS('Base completa'!$A$2:$A$183,$A6,'Base completa'!$H$2:$H$183,"Micro (3k–30k)") -> 6 | E6: =COUNTIFS('Base completa'!$A$2:$A$183,$A6,'Base completa'!$H$2:$H$183,"Média (30k–100k)") -> 2 | F6: =COUNTIFS('Base completa'!$A$2:$A$183,$A6,'Base completa'!$H$2:$H$183,"Macro (100k–500k)") -> 0 | G6: =COUNTIFS('Base completa'!$A$2:$A$183,$A6,'Base completa'!$H$2:$H$183,"Mega (500k+)") -> 0 | H6: =COUNTIFS('Base completa'!$A$2:$A$183,$A6,'Base completa'!$F$2:$F$183,"Mulher") -> 7 | I6: =COUNTIFS('Base completa'!$A$2:$A$183,$A6,'Base completa'!$F$2:$F$183,"Homem") -> 1 | J6: =COUNTIFS('Base completa'!$A$2:$A$183,$A6,'Base completa'!$E$2:$E$183,"Criador(a)") -> 4 | K6: =COUNTIFS('Base completa'!$A$2:$A$183,$A6,'Base completa'!$E$2:$E$183,"Especialista que cria conteúdo") -> 4 | L6: =COUNTIFS('Base completa'!$A$2:$A$183,$A6,'Base completa'!$E$2:$E$183,"Página local / guia") -> 1 | M6: =COUNTIFS('Base completa'!$A$2:$A$183,$A6,'Base completa'!$X$2:$X$183,"Alta") -> 3 | N6: =IFERROR(ROUND(AVERAGEIF('Base completa'!$A$2:$A$183,$A6,'Base completa'!$Y$2:$Y$183),0),"") -> 46
A7: Itapema | B7: =COUNTIF('Base completa'!$A$2:$A$183,$A7) -> 34 | C7: =COUNTIFS('Base completa'!$A$2:$A$183,$A7,'Base completa'!$H$2:$H$183,"Nano (1k–3k)") -> 13 | D7: =COUNTIFS('Base completa'!$A$2:$A$183,$A7,'Base completa'!$H$2:$H$183,"Micro (3k–30k)") -> 12 | E7: =COUNTIFS('Base completa'!$A$2:$A$183,$A7,'Base completa'!$H$2:$H$183,"Média (30k–100k)") -> 7 | F7: =COUNTIFS('Base completa'!$A$2:$A$183,$A7,'Base completa'!$H$2:$H$183,"Macro (100k–500k)") -> 2 | G7: =COUNTIFS('Base completa'!$A$2:$A$183,$A7,'Base completa'!$H$2:$H$183,"Mega (500k+)") -> 0 | H7: =COUNTIFS('Base completa'!$A$2:$A$183,$A7,'Base completa'!$F$2:$F$183,"Mulher") -> 16 | I7: =COUNTIFS('Base completa'!$A$2:$A$183,$A7,'Base completa'!$F$2:$F$183,"Homem") -> 10 | J7: =COUNTIFS('Base completa'!$A$2:$A$183,$A7,'Base completa'!$E$2:$E$183,"Criador(a)") -> 17 | K7: =COUNTIFS('Base completa'!$A$2:$A$183,$A7,'Base completa'!$E$2:$E$183,"Especialista que cria conteúdo") -> 9 | L7: =COUNTIFS('Base completa'!$A$2:$A$183,$A7,'Base completa'!$E$2:$E$183,"Página local / guia") -> 8 | M7: =COUNTIFS('Base completa'!$A$2:$A$183,$A7,'Base completa'!$X$2:$X$183,"Alta") -> 6 | N7: =IFERROR(ROUND(AVERAGEIF('Base completa'!$A$2:$A$183,$A7,'Base completa'!$Y$2:$Y$183),0),"") -> 48
A8: Total | B8: =SUM(B4:B7) -> 182 | C8: =SUM(C4:C7) -> 42 | D8: =SUM(D4:D7) -> 94 | E8: =SUM(E4:E7) -> 31 | F8: =SUM(F4:F7) -> 12 | G8: =SUM(G4:G7) -> 3 | H8: =SUM(H4:H7) -> 109 | I8: =SUM(I4:I7) -> 42 | ... M8: =SUM(M4:M7) -> 61 | N8: =IFERROR(ROUND(AVERAGE('Base completa'!$Y$2:$Y$183),0),"") -> 47
A10: Criadores por nicho e cidade (um perfil conta em cada nicho em que aparece)
A11: Nicho | B11: Itajaí | C11: Balneário Camboriú | D11: Camboriú | E11: Itapema | F11: Total
A12: UGC | B12: =COUNTIFS('Base completa'!$A$2:$A$183,"Itajaí",'Base completa'!$W$2:$W$183,"*"&$A12&"*") -> 3 | C12: =COUNTIFS('Base completa'!$A$2:$A$183,"Balneário Camboriú",'Base completa'!$W$2:$W$183,"*"&$A12&"*") -> 1 | D12: =COUNTIFS('Base completa'!$A$2:$A$183,"Camboriú",'Base completa'!$W$2:$W$183,"*"&$A12&"*") -> 0 | E12: =COUNTIFS('Base completa'!$A$2:$A$183,"Itapema",'Base completa'!$W$2:$W$183,"*"&$A12&"*") -> 1 | F12: =SUM(B12:E12) -> 5
A13: Lifestyle | B13: =COUNTIFS('Base completa'!$A$2:$A$183,"Itajaí",'Base completa'!$W$2:$W$183,"*"&$A13&"*") -> 13 | C13: =COUNTIFS('Base completa'!$A$2:$A$183,"Balneário Camboriú",'Base completa'!$W$2:$W$183,"*"&$A13&"*") -> 16 | D13: =COUNTIFS('Base completa'!$A$2:$A$183,"Camboriú",'Base completa'!$W$2:$W$183,"*"&$A13&"*") -> 0 | E13: =COUNTIFS('Base completa'!$A$2:$A$183,"Itapema",'Base completa'!$W$2:$W$183,"*"&$A13&"*") -> 4 | F13: =SUM(B13:E13) -> 33
A14: Beleza | B14: =COUNTIFS('Base completa'!$A$2:$A$183,"Itajaí",'Base completa'!$W$2:$W$183,"*"&$A14&"*") -> 5 | C14: =COUNTIFS('Base completa'!$A$2:$A$183,"Balneário Camboriú",'Base completa'!$W$2:$W$183,"*"&$A14&"*") -> 9 | D14: =COUNTIFS('Base completa'!$A$2:$A$183,"Camboriú",'Base completa'!$W$2:$W$183,"*"&$A14&"*") -> 0 | E14: =COUNTIFS('Base completa'!$A$2:$A$183,"Itapema",'Base completa'!$W$2:$W$183,"*"&$A14&"*") -> 3 | F14: =SUM(B14:E14) -> 17
A15: Moda | B15: =COUNTIFS('Base completa'!$A$2:$A$183,"Itajaí",'Base completa'!$W$2:$W$183,"*"&$A15&"*") -> 6 | C15: =COUNTIFS('Base completa'!$A$2:$A$183,"Balneário Camboriú",'Base completa'!$W$2:$W$183,"*"&$A15&"*") -> 10 | D15: =COUNTIFS('Base completa'!$A$2:$A$183,"Camboriú",'Base completa'!$W$2:$W$183,"*"&$A15&"*") -> 1 | E15: =COUNTIFS('Base completa'!$A$2:$A$183,"Itapema",'Base completa'!$W$2:$W$183,"*"&$A15&"*") -> 2 | F15: =SUM(B15:E15) -> 19
A16: Fitness e wellness | B16: =COUNTIFS('Base completa'!$A$2:$A$183,"Itajaí",'Base completa'!$W$2:$W$183,"*"&$A16&"*") -> 10 | C16: =COUNTIFS('Base completa'!$A$2:$A$183,"Balneário Camboriú",'Base completa'!$W$2:$W$183,"*"&$A16&"*") -> 18 | D16: =COUNTIFS('Base completa'!$A$2:$A$183,"Camboriú",'Base completa'!$W$2:$W$183,"*"&$A16&"*") -> 3 | E16: =COUNTIFS('Base completa'!$A$2:$A$183,"Itapema",'Base completa'!$W$2:$W$183,"*"&$A16&"*") -> 8 | F16: =SUM(B16:E16) -> 39
A17: Gastronomia | B17: =COUNTIFS('Base completa'!$A$2:$A$183,"Itajaí",'Base completa'!$W$2:$W$183,"*"&$A17&"*") -> 9 | C17: =COUNTIFS('Base completa'!$A$2:$A$183,"Balneário Camboriú",'Base completa'!$W$2:$W$183,"*"&$A17&"*") -> 12 | D17: =COUNTIFS('Base completa'!$A$2:$A$183,"Camboriú",'Base completa'!$W$2:$W$183,"*"&$A17&"*") -> 1 | E17: =COUNTIFS('Base completa'!$A$2:$A$183,"Itapema",'Base completa'!$W$2:$W$183,"*"&$A17&"*") -> 3 | F17: =SUM(B17:E17) -> 25
A18: Viagem | B18: =COUNTIFS('Base completa'!$A$2:$A$183,"Itajaí",'Base completa'!$W$2:$W$183,"*"&$A18&"*") -> 9 | C18: =COUNTIFS('Base completa'!$A$2:$A$183,"Balneário Camboriú",'Base completa'!$W$2:$W$183,"*"&$A18&"*") -> 9 | D18: =COUNTIFS('Base completa'!$A$2:$A$183,"Camboriú",'Base completa'!$W$2:$W$183,"*"&$A18&"*") -> 1 | E18: =COUNTIFS('Base completa'!$A$2:$A$183,"Itapema",'Base completa'!$W$2:$W$183,"*"&$A18&"*") -> 7 | F18: =SUM(B18:E18) -> 26
A19: Entretenimento e humor | B19: =COUNTIFS('Base completa'!$A$2:$A$183,"Itajaí",'Base completa'!$W$2:$W$183,"*"&$A19&"*") -> 7 | C19: =COUNTIFS('Base completa'!$A$2:$A$183,"Balneário Camboriú",'Base completa'!$W$2:$W$183,"*"&$A19&"*") -> 8 | D19: =COUNTIFS('Base completa'!$A$2:$A$183,"Camboriú",'Base completa'!$W$2:$W$183,"*"&$A19&"*") -> 0 | E19: =COUNTIFS('Base completa'!$A$2:$A$183,"Itapema",'Base completa'!$W$2:$W$183,"*"&$A19&"*") -> 4 | F19: =SUM(B19:E19) -> 19
A20: Finanças | B20: =COUNTIFS('Base completa'!$A$2:$A$183,"Itajaí",'Base completa'!$W$2:$W$183,"*"&$A20&"*") -> 3 | C20: =COUNTIFS('Base completa'!$A$2:$A$183,"Balneário Camboriú",'Base completa'!$W$2:$W$183,"*"&$A20&"*") -> 2 | D20: =COUNTIFS('Base completa'!$A$2:$A$183,"Camboriú",'Base completa'!$W$2:$W$183,"*"&$A20&"*") -> 0 | E20: =COUNTIFS('Base completa'!$A$2:$A$183,"Itapema",'Base completa'!$W$2:$W$183,"*"&$A20&"*") -> 4 | F20: =SUM(B20:E20) -> 9
A21: Casa e organização | B21: =COUNTIFS('Base completa'!$A$2:$A$183,"Itajaí",'Base completa'!$W$2:$W$183,"*"&$A21&"*") -> 9 | C21: =COUNTIFS('Base completa'!$A$2:$A$183,"Balneário Camboriú",'Base completa'!$W$2:$W$183,"*"&$A21&"*") -> 10 | D21: =COUNTIFS('Base completa'!$A$2:$A$183,"Camboriú",'Base completa'!$W$2:$W$183,"*"&$A21&"*") -> 2 | E21: =COUNTIFS('Base completa'!$A$2:$A$183,"Itapema",'Base completa'!$W$2:$W$183,"*"&$A21&"*") -> 2 | F21: =SUM(B21:E21) -> 23
A22: Tecnologia | B22: =COUNTIFS('Base completa'!$A$2:$A$183,"Itajaí",'Base completa'!$W$2:$W$183,"*"&$A22&"*") -> 0 | C22: =COUNTIFS('Base completa'!$A$2:$A$183,"Balneário Camboriú",'Base completa'!$W$2:$W$183,"*"&$A22&"*") -> 0 | D22: =COUNTIFS('Base completa'!$A$2:$A$183,"Camboriú",'Base completa'!$W$2:$W$183,"*"&$A22&"*") -> 0 | E22: =COUNTIFS('Base completa'!$A$2:$A$183,"Itapema",'Base completa'!$W$2:$W$183,"*"&$A22&"*") -> 0 | F22: =SUM(B22:E22) -> 0
A23: Negócios e empreendedorismo | B23: =COUNTIFS('Base completa'!$A$2:$A$183,"Itajaí",'Base completa'!$W$2:$W$183,"*"&$A23&"*") -> 16 | C23: =COUNTIFS('Base completa'!$A$2:$A$183,"Balneário Camboriú",'Base completa'!$W$2:$W$183,"*"&$A23&"*") -> 17 | D23: =COUNTIFS('Base completa'!$A$2:$A$183,"Camboriú",'Base completa'!$W$2:$W$183,"*"&$A23&"*") -> 2 | E23: =COUNTIFS('Base completa'!$A$2:$A$183,"Itapema",'Base completa'!$W$2:$W$183,"*"&$A23&"*") -> 4 | F23: =SUM(B23:E23) -> 39
... A28: Dicas locais | B28: =COUNTIFS('Base completa'!$A$2:$A$183,"Itajaí",'Base completa'!$W$2:$W$183,"*"&$A28&"*") -> 11 | C28: =COUNTIFS('Base completa'!$A$2:$A$183,"Balneário Camboriú",'Base completa'!$W$2:$W$183,"*"&$A28&"*") -> 18 | D28: =COUNTIFS('Base completa'!$A$2:$A$183,"Camboriú",'Base completa'!$W$2:$W$183,"*"&$A28&"*") -> 0 | E28: =COUNTIFS('Base completa'!$A$2:$A$183,"Itapema",'Base completa'!$W$2:$W$183,"*"&$A28&"*") -> 5 | F28: =SUM(B28:E28) -> 34

Sheet Base completa
A1: Cidade principal | B1: Também atua em | C1: Perfil | D1: Nome | E1: Tipo | F1: Criador(a) | G1: Seguidores | H1: Faixa | I1: Engajamento | J1: Engaj. de referência | K1: Engaj. vs referência | L1: Média de curtidas | M1: Média de comentários | N1: Views medianas (reels) | O1: Views/seguidores | P1: % vídeos | Q1: Posts/semana | R1: Último post | S1: Dias sem postar | T1: Publis (de 12) | U1: Marcas em publis | V1: Nicho principal | W1: Nichos | X1: Fit CRIA | Y1: Score (0-100) | Z1: Categoria no IG | AA1: Verificado | AB1: Link na bio | AC1: Canal de contato | AD1: Como confirmei a cidade | AE1: Locais marcados | AF1: Bio | AG1: Link | AH1: Status | AI1: Observações
A2: Itajaí | C2: @thaisedemari | D2: Thaise de Mari | E2: Criador(a) | F2: Mulher | G2: 1049161 | H2: Mega (500k+) | I2: 0.0015 | J2: =IFERROR(INDEX('Como ler'!$B$20:$B$24,MATCH(H2,'Como ler'!$A$20:$A$24,0)),"") -> 0.007 | K2: =IF(OR(I2="",J2=""),"",I2/J2) -> 0.21428571 | L2: 2112 | M2: 86.8 | N2: 19137 | O2: =IF(OR(N2="",G2=0),"",N2/G2) -> 0.018240289 | P2: 0.42 | Q2: 0.9 | R2: 46286 | S2: =IF(R2="","",'Como ler'!$B$27-R2) -> 6 | T2: 0 | V2: Beleza | W2: Beleza, Negócios e empreendedorismo, Lifestyle, Moda | X2: Alta | Y2: =ROUND(IF(K2="",0,MIN(40,40*K2/1.5))+IF(S2="",0,IF(S2<=7,20,IF(S2<=30,12,IF(S2<=90,5,0))))+IF(Q2="",0,MIN(15,Q2*5))+IF(O2="",0,MIN(15,O2*30))+IF(E2="Criador(a)",10,IF(E2="Especialista que cria conteúdo",6,4)),0) -> 41 | Z2: Entrepreneur | AD2: Itajaí: bio | AE2: Barcelona, España (2), Formentera, Islas Baleares, Spain (2), Ibiza, Spain (2), Rio de Janeiro, Rio de Janeiro (1) | AF2: Fashion • Beauty • Lifestyle • Travel • Real life / Founder @nowwabrand / Caixa Postal 46 Itajaí-SC Cep 88301-970 | AG2: https://instagram.com/thaisedemari | AH2: Não contatada
A3: Itajaí | C3: @lucasmirandasc | D3: Lucas Miranda | E3: Criador(a) | F3: Homem | G3: 189201 | H3: Macro (100k–500k) | I3: 0.0033 | J3: =IFERROR(INDEX('Como ler'!$B$20:$B$24,MATCH(H3,'Como ler'!$A$20:$A$24,0)),"") -> 0.01 | K3: =IF(OR(I3="",J3=""),"",I3/J3) -> 0.33 | L3: 1060 | M3: 57.3 | N3: 22196 | O3: =IF(OR(N3="",G3=0),"",N3/G3) -> 0.11731439 | P3: 0.67 | Q3: 0.7 | R3: 46292 | S3: =IF(R3="","",'Como ler'!$B$27-R3) -> 0 | T3: 0 | V3: Gastronomia | W3: Gastronomia, Fitness e wellness, Viagem | X3: Baixa | Y3: =ROUND(IF(K3="",0,MIN(40,40*K3/1.5))+IF(S3="",0,IF(S3<=7,20,IF(S3<=30,12,IF(S3<=90,5,0))))+IF(Q3="",0,MIN(15,Q3*5))+IF(O3="",0,MIN(15,O3*30))+IF(E3="Criador(a)",10,IF(E3="Especialista que cria conteúdo",6,4)),0) -> 46 | Z3: Digital creator | AD3: Itajaí: bio, 2 post(s) marcados | AE3: Itajaí- Santa Catarina (2) | AF3: Itajaí - SC📍 / Hospedagens | Gastronomia / MISTER LAS AMÉRICAS ITAJAÍ 2026 / Embaixador: @lfmen @mancluboficial @3coracoes @maxinutrioficial @academia.ad3 | AG3: https://instagram.com/lucasmirandasc | AH3: Não contatada
A4: Itajaí | C4: @superdicasnaestrada | D4: Super Dicas na Estrada - Lucas e Maitê | E4: Criador(a) | F4: Homem | G4: 100790 | H4: Macro (100k–500k) | J4: =IFERROR(INDEX('Como ler'!$B$20:$B$24,MATCH(H4,'Como ler'!$A$20:$A$24,0)),"") -> 0.01 | K4: =IF(OR(I4="",J4=""),"",I4/J4) | M4: 48.2 | N4: 2518 | O4: =IF(OR(N4="",G4=0),"",N4/G4) -> 0.024982637 | P4: 0.89 | Q4: 1.5 | R4: 46284 | S4: =IF(R4="","",'Como ler'!$B$27-R4) -> 8 | T4: 0 | V4: Dicas locais | W4: Dicas locais, Gastronomia | X4: Baixa | Y4: =ROUND(IF(K4="",0,MIN(40,40*K4/1.5))+IF(S4="",0,IF(S4<=7,20,IF(S4<=30,12,IF(S4<=90,5,0))))+IF(Q4="",0,MIN(15,Q4*5))+IF(O4="",0,MIN(15,O4*30))+IF(E4="Criador(a)",10,IF(E4="Especialista que cria conteúdo",6,4)),0) -> 30 | Z4: Digital creator | AB4: Sim | AC4: whats | AD4: Itajaí: 1 post(s) marcados | AE4: Blumenau, Santa Catarina, Brazil (2), Piçarras (1), Rodeio (1), Itajaí -SC (1) | AF4: 🌎 Super Dicas pelas estradas do Sul do Brasil! / 🚀+ de 600 empresas parceiras! / ⭐️ Divulgue sua marca aqui! / ⬇️ Contato Whats: | AG4: https://instagram.com/superdicasnaestrada | AH4: Não contatada | AI4: Curtidas ocultas: engajamento calculado só com posts visíveis ou indisponível
A5: Itajaí | C5: @raissaarcanjo | D5: Raíssa Arcanjo | E5: Criador(a) | F5: Mulher | G5: 89409 | H5: Média (30k–100k) | I5: 0.0014 | J5: =IFERROR(INDEX('Como ler'!$B$20:$B$24,MATCH(H5,'Como ler'!$A$20:$A$24,0)),"") -> 0.015 | K5: =IF(OR(I5="",J5=""),"",I5/J5) -> 0.093333333 | L5: 264 | M5: 41.7 | N5: 1456 | O5: =IF(OR(N5="",G5=0),"",N5/G5) -> 0.016284714 | P5: 0.67 | Q5: 6.2 | R5: 46289 | S5: =IF(R5="","",'Como ler'!$B$27-R5) -> 3 | T5: 0 | V5: Negócios e empreendedorismo | W5: Negócios e empreendedorismo | X5: Alta | Y5: =ROUND(IF(K5="",0,MIN(40,40*K5/1.5))+IF(S5="",0,IF(S5<=7,20,IF(S5<=30,12,IF(S5<=90,5,0))))+IF(Q5="",0,MIN(15,Q5*5))+IF(O5="",0,MIN(15,O5*30))+IF(E5="Criador(a)",10,IF(E5="Especialista que cria conteúdo",6,4)),0) -> 48 | Z5: Digital creator | AA5: Sim | AB5: Sim | AD5: Itajaí: 4 post(s) marcados | AE5: Itajaí (4), Greenvalley (1), Balneário Shopping (1), Navegantes (1) | AF5: Geralmente posto muitooo. 🗣️ / Palestrante, Mentora, Influenciadora, Empreendedora, Colunista Social. 🧠 / VICIADA EM VER GENTE VENCENDO NA VIDA! 🫀 | AG5: https://instagram.com/raissaarcanjo | AH5: Não contatada
A6: Itajaí | C6: @itajaisc_ | D6: Renildo Figueiredo 😎 | E6: Criador(a) | F6: Homem | G6: 83440 | H6: Média (30k–100k) | I6: 0.0109 | J6: =IFERROR(INDEX('Como ler'!$B$20:$B$24,MATCH(H6,'Como ler'!$A$20:$A$24,0)),"") -> 0.015 | K6: =IF(OR(I6="",J6=""),"",I6/J6) -> 0.72666667 | L6: 1267 | M6: 140 | N6: 9851 | O6: =IF(OR(N6="",G6=0),"",N6/G6) -> 0.11806088 | P6: 0.9 | Q6: 15.8 | R6: 46291 | S6: =IF(R6="","",'Como ler'!$B$27-R6) -> 1 | T6: 0 | V6: Finanças | W6: Finanças, Dicas locais, Entretenimento e humor, Família e maternidade | X6: Média | Y6: =ROUND(IF(K6="",0,MIN(40,40*K6/1.5))+IF(S6="",0,IF(S6<=7,20,IF(S6<=30,12,IF(S6<=90,5,0))))+IF(Q6="",0,MIN(15,Q6*5))+IF(O6="",0,MIN(15,O6*30))+IF(E6="Criador(a)",10,IF(E6="Especialista que cria conteúdo",6,4)),0) -> 68 | AC6: direct | AD6: Itajaí: bio, 7 post(s) marcados | AE6: Itajaí, Santa Catarina, Brasil (6), Parrilla 674 (2), Balneário Piçarras - SC (1), Itajaí (1) | AF6: Um Nortista🛫 vivendo em 🛬Itajaí😎 / 🌴 Itajaí & SC sem filtros / 🏡 Onde morar, passear e investir / 💰 Custo de vida, dicas e lazer / 📲 parceiras via Direct | AG6: https://instagram.com/itajaisc_ | AH6: Não contatada
A7: Itajaí | C7: @nubiakatyoficial | D7: Núbia | Mãe & Blogueira • Itajai | E7: Criador(a) | F7: Mulher | G7: 78728 | H7: Média (30k–100k) | I7: 0.0063 | J7: =IFERROR(INDEX('Como ler'!$B$20:$B$24,MATCH(H7,'Como ler'!$A$20:$A$24,0)),"") -> 0.015 | K7: =IF(OR(I7="",J7=""),"",I7/J7) -> 0.42 | L7: 543 | M7: 26.1 | N7: 5011 | O7: =IF(OR(N7="",G7=0),"",N7/G7) -> 0.063649527 | P7: 0.9 | Q7: 15.8 | R7: 46292 | S7: =IF(R7="","",'Como ler'!$B$27-R7) -> 0 | T7: 0 | V7: Entretenimento e humor | W7: Entretenimento e humor, Família e maternidade | X7: Média | Y7: =ROUND(IF(K7="",0,MIN(40,40*K7/1.5))+IF(S7="",0,IF(S7<=7,20,IF(S7<=30,12,IF(S7<=90,5,0))))+IF(Q7="",0,MIN(15,Q7*5))+IF(O7="",0,MIN(15,O7*30))+IF(E7="Criador(a)",10,IF(E7="Especialista que cria conteúdo",6,4)),0) -> 58 | Z7: Digital creator | AA7: Sim | AD7: Itajaí: bio, 8 post(s) marcados | AE7: Itajaí -SC (7), Itajaí (1) | AF7: 🗣️| FALA MEUX QUIRIDU. TAX TOLO ? / 🩷| MÃE DE DOIS BOCA DE SACOLA / 📍| ITAJAÍ | +70 MILHÕES DE VIEWS TÁ ? | AG7: https://instagram.com/nubiakatyoficial | AH7: Não contatada
A8: Itajaí | C8: @eogriilo | D8: Geovane José - Influencer de Itajaí | E8: Criador(a) | F8: Homem | G8: 76287 | H8: Média (30k–100k) | I8: 0.0016 | J8: =IFERROR(INDEX('Como ler'!$B$20:$B$24,MATCH(H8,'Como ler'!$A$20:$A$24,0)),"") -> 0.015 | K8: =IF(OR(I8="",J8=""),"",I8/J8) -> 0.10666667 | L8: 136 | M8: 16.4 | N8: 2219 | O8: =IF(OR(N8="",G8=0),"",N8/G8) -> 0.029087525 | P8: 0.9 | Q8: 21 | R8: 46292 | S8: =IF(R8="","",'Como ler'!$B$27-R8) -> 0 | T8: 0 | V8: Entretenimento e humor | W8: Entretenimento e humor, Negócios e empreendedorismo | X8: Alta | Y8: =ROUND(IF(K8="",0,MIN(40,40*K8/1.5))+IF(S8="",0,IF(S8<=7,20,IF(S8<=30,12,IF(S8<=90,5,0))))+IF(Q8="",0,MIN(15,Q8*5))+IF(O8="",0,MIN(15,O8*30))+IF(E8="Criador(a)",10,IF(E8="Especialista que cria conteúdo",6,4)),0) -> 49 | Z8: Digital creator | AA8: Sim | AD8: Itajaí: bio, 8 post(s) marcados | AE8: Itajaí -SC (6), São Vicente, Itajaí (2) | AF8: Fala comigo, tropa. / Empresário | Influencer | Dono de Barbearia / Proprietário da @nareguaitajai / Publicidade: @agenciachammma / Itajaí Sc | AG8: https://instagram.com/eogriilo | AH8: Não contatada
A9: Itajaí | C9: @gabryelnuness | D9: Gabryel Nunes - Influenciador de Itajaí | E9: Criador(a) | F9: Homem | G9: 69075 | H9: Média (30k–100k) | I9: 0.0037 | J9: =IFERROR(INDEX('Como ler'!$B$20:$B$24,MATCH(H9,'Como ler'!$A$20:$A$24,0)),"") -> 0.015 | K9: =IF(OR(I9="",J9=""),"",I9/J9) -> 0.24666667 | L9: 430 | M9: 51.8 | N9: 4448 | O9: =IF(OR(N9="",G9=0),"",N9/G9) -> 0.064393775 | P9: 0.83 | Q9: 77 | R9: 46291 | S9: =IF(R9="","",'Como ler'!$B$27-R9) -> 1 | T9: 0 | V9: Negócios e empreendedorismo | W9: Negócios e empreendedorismo, Entretenimento e humor | X9: Alta | Y9: =ROUND(IF(K9="",0,MIN(40,40*K9/1.5))+IF(S9="",0,IF(S9<=7,20,IF(S9<=30,12,IF(S9<=90,5,0))))+IF(Q9="",0,MIN(15,Q9*5))+IF(O9="",0,MIN(15,O9*30))+IF(E9="Criador(a)",10,IF(E9="Especialista que cria conteúdo",6,4)),0) -> 54 | Z9: Digital creator | AD9: Itajaí: 9 post(s) marcados | AE9: Itajaí (9), Estefano Jose Vanolli (1), Pizzaria Herois da Pizza (1) | AF9: 🎙️ FALA COMIGO RAPAZEADA / 🎤 Influencer • Empresário • Comunicador / 📲 Publicidades • @agenciachammma | AG9: https://instagram.com/gabryelnuness | AH9: Não contatada
A10: Itajaí | B10: Balneário Camboriú | C10: @julianadomareski | D10: Juliana Domareski | E10: Especialista que cria conteúdo | F10: Mulher | G10: 65364 | H10: Média (30k–100k) | I10: 0.0039 | J10: =IFERROR(INDEX('Como ler'!$B$20:$B$24,MATCH(H10,'Como ler'!$A$20:$A$24,0)),"") -> 0.015 | K10: =IF(OR(I10="",J10=""),"",I10/J10) -> 0.26 | L10: 339 | M10: 7.1 | N10: 5204 | O10: =IF(OR(N10="",G10=0),"",N10/G10) -> 0.079615691 | P10: 0.7 | Q10: 2.1 | R10: 46291 | S10: =IF(R10="","",'Como ler'!$B$27-R10) -> 1 | T10: 0 | V10: Viagem | W10: Viagem, Negócios e empreendedorismo, Casa e organização | X10: Alta | Y10: =ROUND(IF(K10="",0,MIN(40,40*K10/1.5))+IF(S10="",0,IF(S10<=7,20,IF(S10<=30,12,IF(S10<=90,5,0))))+IF(Q10="",0,MIN(15,Q10*5))+IF(O10="",0,MIN(15,O10*30))+IF(E10="Criador(a)",10,IF(E10="Especialista que cria conteúdo",6,4)),0) -> 46 | Z10: None | AA10: Sim | AB10: Sim | AD10: Itajaí: bio, 2 post(s) marcados; Balneário Camboriú: bio, 2 post(s) marcados | AE10: Imobiliária Terra (3), Balneário Camboriú (2), Praia Brava - Itajaí/SC (2), Copacabana, Rio de Janeiro (1) | AF10: CEO / Grupo Domma | @terra_imobiliaria / Estruturação de operações imobiliárias para quem quer multiplicar capital. / Balneário Camboriú • Praia Brava • SC | AG10: https://instagram.com/julianadomareski | AH10: Não contatada
A11: Itajaí | C11: @gabyoliveirasc | D11: Gabriela Oliveira | Casamento cristão & Vida real | E11: Especialista que cria conteúdo | F11: Mulher | G11: 52669 | H11: Média (30k–100k) | I11: 0.002 | J11: =IFERROR(INDEX('Como ler'!$B$20:$B$24,MATCH(H11,'Como ler'!$A$20:$A$24,0)),"") -> 0.015 | K11: =IF(OR(I11="",J11=""),"",I11/J11) -> 0.13333333 | L11: 92 | M11: 7.3 | N11: 1675 | O11: =IF(OR(N11="",G11=0),"",N11/G11) -> 0.031802389 | P11: 0.27 | Q11: 5 | R11: 46286 | S11: =IF(R11="","",'Como ler'!$B$27-R11) -> 6 | T11: 0 | V11: Relacionamento | W11: Relacionamento, Família e maternidade, Lifestyle, Educação e conhecimento | X11: Média | Y11: =ROUND(IF(K11="",0,MIN(40,40*K11/1.5))+IF(S11="",0,IF(S11<=7,20,IF(S11<=30,12,IF(S11<=90,5,0))))+IF(Q11="",0,MIN(15,Q11*5))+IF(O11="",0,MIN(15,O11*30))+IF(E11="Criador(a)",10,IF(E11="Especialista que cria conteúdo",6,4)),0) -> 46 | Z11: Digital creator | AD11: Itajaí: bio, 2 post(s) marcados | AE11: Itajaí -SC (2) | AF11: Psicóloga • Terapeuta de casais • Esposa / Mãe do Joaquim, à espera do Jonatas 🤰🏻 / ✝️ Fé, casamento & vida real / 📍 Itajaí/SC | AG11: https://instagram.com/gabyoliveirasc | AH11: Não contatada
A12: Itajaí | B12: Balneário Camboriú | C12: @tatypassos__ | D12: Taty Passos | Explore SC | E12: Criador(a) | F12: Mulher | G12: 48271 | H12: Média (30k–100k) | I12: 0.0009 | J12: =IFERROR(INDEX('Como ler'!$B$20:$B$24,MATCH(H12,'Como ler'!$A$20:$A$24,0)),"") -> 0.015 | K12: =IF(OR(I12="",J12=""),"",I12/J12) -> 0.06 | L12: 37 | M12: 7 | N12: 286 | O12: =IF(OR(N12="",G12=0),"",N12/G12) -> 0.0059248824 | P12: 0.56 | Q12: 0.8 | R12: 46292 | S12: =IF(R12="","",'Como ler'!$B$27-R12) -> 0 | T12: 0 | V12: Gastronomia | W12: Gastronomia, Beleza, Entretenimento e humor, Casa e organização | X12: Alta | Y12: =ROUND(IF(K12="",0,MIN(40,40*K12/1.5))+IF(S12="",0,IF(S12<=7,20,IF(S12<=30,12,IF(S12<=90,5,0))))+IF(Q12="",0,MIN(15,Q12*5))+IF(O12="",0,MIN(15,O12*30))+IF(E12="Criador(a)",10,IF(E12="Especialista que cria conteúdo",6,4)),0) -> 36 | Z12: Digital creator | AB12: Sim | AD12: Itajaí: 1 post(s) marcados; Balneário Camboriú: 1 post(s) marcados | AE12: Balneário Piçarras (2), Curitiba, Paraná (1), Balneário Piçarras - SC (1), Itajaí (1) | AF12: 🦋Os padrões de beleza que lutem para se encaixar em mim! / 🚀Foguete tem ré sim, mas não comigo / 🍽️Gastronomia & Humor / @exploresantacatarina @casadataty__ | AG12: https://instagram.com/tatypassos__ | AH12: Não contatada
A13: Itajaí | C13: @toemdrika | D13: Drika | Influenciadora em Santa Catarina | E13: Criador(a) | F13: Mulher | G13: 42854 | H13: Média (30k–100k) | I13: 0.0101 | J13: =IFERROR(INDEX('Como ler'!$B$20:$B$24,MATCH(H13,'Como ler'!$A$20:$A$24,0)),"") -> 0.015 | K13: =IF(OR(I13="",J13=""),"",I13/J13) -> 0.67333333 | L13: 769 | M13: 80.4 | N13: 3651 | O13: =IF(OR(N13="",G13=0),"",N13/G13) -> 0.085196248 | P13: 1 | Q13: 6.4 | R13: 46288 | S13: =IF(R13="","",'Como ler'!$B$27-R13) -> 4 | T13: 1 | U13: @promenacmotoshonda | V13: Fitness e wellness | W13: Fitness e wellness, Lifestyle | X13: Média | Y13: =ROUND(IF(K13="",0,MIN(40,40*K13/1.5))+IF(S13="",0,IF(S13<=7,20,IF(S13<=30,12,IF(S13<=90,5,0))))+IF(Q13="",0,MIN(15,Q13*5))+IF(O13="",0,MIN(15,O13*30))+IF(E13="Criador(a)",10,IF(E13="Especialista que cria conteúdo",6,4)),0) -> 66 | AC13: email | AD13: Itajaí: bio, 3 post(s) marcados | AE13: Itajaí (3), Piçarras (1) | AF13: 📍Baiana em Itajaí / 📧 [e-mail na bio] / 🏋🏾‍♀️Embaixadora @pratiquefitness / Quer se mudar pra SC? Eu te ajudo👇 | AG13: https://instagram.com/toemdrika | AH13: Não contatada
A14: Itajaí | B14: Itapema | C14: @mordomorodrigo_oficial | D14: Mordomo Rodrig️o | E14: Criador(a) | F14: Homem | G14: 27951 | H14: Micro (3k–30k) | I14: 0.0096 | J14: =IFERROR(INDEX('Como ler'!$B$20:$B$24,MATCH(H14,'Como ler'!$A$20:$A$24,0)),"") -> 0.025 | K14: =IF(OR(I14="",J14=""),"",I14/J14) -> 0.384 | L14: 200 | M14: 38.7 | N14: 2117 | O14: =IF(OR(N14="",G14=0),"",N14/G14) -> 0.075739687 | P14: 0.9 | Q14: 1.4 | R14: 46291 | S14: =IF(R14="","",'Como ler'!$B$27-R14) -> 1 | T14: 0 | V14: Relacionamento | W14: Relacionamento | X14: Baixa | Y14: =ROUND(IF(K14="",0,MIN(40,40*K14/1.5))+IF(S14="",0,IF(S14<=7,20,IF(S14<=30,12,IF(S14<=90,5,0))))+IF(Q14="",0,MIN(15,Q14*5))+IF(O14="",0,MIN(15,O14*30))+IF(E14="Criador(a)",10,IF(E14="Especialista que cria conteúdo",6,4)),0) -> 50 | AD14: Itajaí: bio, 1 post(s) marcados; Itapema: 2 post(s) marcados | AE14: Itapema, Santa Catarina, Brazil (2), Florianópolis, Santa Catarina, Brasil (2), Brasil Santa Catarina (1), Praia Brava - Itajaí/SC (1) | AF14: ⚫Influencer/Itajaí SC / PR 😊 / ⚫Mordomo de noivas / ⚫Mordomo das estrelas / ⚫Modelo/Ator/Bailarino / ⚫️❤️🔒🥰 | AG14: https://instagram.com/mordomorodrigo_oficial | AH14: Não contatada
A15: Itajaí | C15: @herique.finatto | D15: Herique Finato | E15: Criador(a) | F15: Homem | G15: 25575 | H15: Micro (3k–30k) | I15: 0.0076 | J15: =IFERROR(INDEX('Como ler'!$B$20:$B$24,MATCH(H15,'Como ler'!$A$20:$A$24,0)),"") -> 0.025 | K15: =IF(OR(I15="",J15=""),"",I15/J15) -> 0.304 | L15: 869 | M15: 2.4 | N15: 3882 | O15: =IF(OR(N15="",G15=0),"",N15/G15) -> 0.15178886 | P15: 0.92 | Q15: 4.8 | R15: 46292 | S15: =IF(R15="","",'Como ler'!$B$27-R15) -> 0 | T15: 0 | V15: Lifestyle | W15: Lifestyle, Fitness e wellness | X15: Média | Y15: =ROUND(IF(K15="",0,MIN(40,40*K15/1.5))+IF(S15="",0,IF(S15<=7,20,IF(S15<=30,12,IF(S15<=90,5,0))))+IF(Q15="",0,MIN(15,Q15*5))+IF(O15="",0,MIN(15,O15*30))+IF(E15="Criador(a)",10,IF(E15="Especialista que cria conteúdo",6,4)),0) -> 58 | AD15: Itajaí: 1 post(s) marcados | AE15: Praia Brava - Itajai (1) | AF15: 🔥 Criador de conteúdo / 🏋🏼 Minha rotina diária nos stories / 🌱Inspirando uma vida saudável e ativa | AG15: https://instagram.com/herique.finatto | AH15: Não contatada
A16: Itajaí | B16: Balneário Camboriú | C16: @shophome.brasil | D16: Shophome | Dicas BC, Itajaí e Região | E16: Página local / guia | F16: Página/marca | G16: 20687 | H16: Micro (3k–30k) | I16: 0.0019 | J16: =IFERROR(INDEX('Como ler'!$B$20:$B$24,MATCH(H16,'Como ler'!$A$20:$A$24,0)),"") -> 0.025 | K16: =IF(OR(I16="",J16=""),"",I16/J16) -> 0.076 | L16: 40 | M16: 7.8 | N16: 867 | O16: =IF(OR(N16="",G16=0),"",N16/G16) -> 0.041910378 | P16: 1 | Q16: 2.4 | R16: 45935 | S16: =IF(R16="","",'Como ler'!$B$27-R16) -> 357 | T16: 0 | V16: Entretenimento e humor | W16: Entretenimento e humor, Dicas locais, Lifestyle, Casa e organização | X16: Alta | Y16: =ROUND(IF(K16="",0,MIN(40,40*K16/1.5))+IF(S16="",0,IF(S16<=7,20,IF(S16<=30,12,IF(S16<=90,5,0))))+IF(Q16="",0,MIN(15,Q16*5))+IF(O16="",0,MIN(15,O16*30))+IF(E16="Criador(a)",10,IF(E16="Especialista que cria conteúdo",6,4)),0) -> 19 | Z16: None | AB16: Sim | AD16: Itajaí: bio; Balneário Camboriú: bio | AF16: 💙Dicas, dia a dia e humor / 📍 Indicações em BC, Itajaí e região / ⬇️ Entre no grupo de ofertas | AG16: https://instagram.com/shophome.brasil | AH16: Não contatada
A17: Itajaí | B17: Balneário Camboriú | C17: @isabelaonofre | D17: Isabela Onofre | E17: Criador(a) | F17: Mulher | G17: 20124 | H17: Micro (3k–30k) | I17: 0.0049 | J17: =IFERROR(INDEX('Como ler'!$B$20:$B$24,MATCH(H17,'Como ler'!$A$20:$A$24,0)),"") -> 0.025 | K17: =IF(OR(I17="",J17=""),"",I17/J17) -> 0.196 | L17: 80 | M17: 32.9 | N17: 845 | O17: =IF(OR(N17="",G17=0),"",N17/G17) -> 0.041989664 | P17: 0.89 | Q17: 5.1 | R17: 46292 | S17: =IF(R17="","",'Como ler'!$B$27-R17) -> 0 | T17: 0 | V17: Fitness e wellness | W17: Fitness e wellness, Dicas locais, Moda | X17: Média | Y17: =ROUND(IF(K17="",0,MIN(40,40*K17/1.5))+IF(S17="",0,IF(S17<=7,20,IF(S17<=30,12,IF(S17<=90,5,0))))+IF(Q17="",0,MIN(15,Q17*5))+IF(O17="",0,MIN(15,O17*30))+IF(E17="Criador(a)",10,IF(E17="Especialista que cria conteúdo",6,4)),0) -> 51 | AA17: Sim | AC17: email | AD17: Balneário Camboriú: 1 post(s) marcados; Itajaí: 3 post(s) marcados | AE17: Itajaí -SC (3), Balneário Camboriú (1), Estação Azul (1), Monthez Hotel & Eventos (1) | AF17: Dicas, treinos, looks e uns surtos de uma geminiana 30+ 💖✌🏻 / “ME DIVERTINDO NO DESCONFORTO” / 💌 Parcerias: [e-mail na bio] | AG17: https://instagram.com/isabelaonofre | AH17: Não contatada
A18: Itajaí | C18: @bevieiraa | D18: Beatriz Vieira | Maquiadora | E18: Criador(a) | F18: Mulher | G18: 17162 | H18: Micro (3k–30k) | I18: 0.0044 | J18: =IFERROR(INDEX('Como ler'!$B$20:$B$24,MATCH(H18,'Como ler'!$A$20:$A$24,0)),"") -> 0.025 | K18: =IF(OR(I18="",J18=""),"",I18/J18) -> 0.176 | L18: 102 | M18: 9.9 | N18: 581 | O18: =IF(OR(N18="",G18=0),"",N18/G18) -> 0.033853863 | P18: 0.67 | Q18: 1.8 | R18: 46291 | S18: =IF(R18="","",'Como ler'!$B$27-R18) -> 1 | T18: 0 | V18: Beleza | W18: Beleza, Viagem, Negócios e empreendedorismo, Educação e conhecimento | X18: Alta | Y18: =ROUND(IF(K18="",0,MIN(40,40*K18/1.5))+IF(S18="",0,IF(S18<=7,20,IF(S18<=30,12,IF(S18<=90,5,0))))+IF(Q18="",0,MIN(15,Q18*5))+IF(O18="",0,MIN(15,O18*30))+IF(E18="Criador(a)",10,IF(E18="Especialista que cria conteúdo",6,4)),0) -> 45 | Z18: Beauty, cosmetic & personal care | AB18: Sim | AD18: Itajaí: bio, 1 post(s) marcados | AE18: Curacao Caribe (1), Itajaí (1), Bloove • Be Vieira (1) | AF18: Beauty, viagens & vida real / Itajaí | SC / Makeup Artist há 12 anos / Fundadora da @bloovebeauty / 💌 Agendamentos • Orçamentos • Cursos • Publicidade ↓ | AG18: https://instagram.com/bevieiraa | AH18: Não contatada
A19: Itajaí | C19: @melissagmenezes | D19: Melissa Menezes | E19: Criador(a) | F19: Mulher | G19: 16490 | H19: Micro (3k–30k) | I19: 0.0101 | J19: =IFERROR(INDEX('Como ler'!$B$20:$B$24,MATCH(H19,'Como ler'!$A$20:$A$24,0)),"") -> 0.025 | K19: =IF(OR(I19="",J19=""),"",I19/J19) -> 0.404 | L19: 162 | M19: 59.8 | N19: 7430 | O19: =IF(OR(N19="",G19=0),"",N19/G19) -> 0.45057611 | P19: 0.18 | Q19: 17.5 | R19: 46292 | S19: =IF(R19="","",'Como ler'!$B$27-R19) -> 0 | T19: 0 | V19: Casa e organização | W19: Casa e organização, Família e maternidade, Educação e conhecimento, Dicas locais | X19: Alta | Y19: =ROUND(IF(K19="",0,MIN(40,40*K19/1.5))+IF(S19="",0,IF(S19<=7,20,IF(S19<=30,12,IF(S19<=90,5,0))))+IF(Q19="",0,MIN(15,Q19*5))+IF(O19="",0,MIN(15,O19*30))+IF(E19="Criador(a)",10,IF(E19="Especialista que cria conteúdo",6,4)),0) -> 69 | Z19: Digital creator | AA19: Sim | AB19: Sim | AD19: Itajaí: bio, 11 post(s) marcados | AE19: Itajaí -SC (6), Itajaí (4), Itajaí, Santa Catarina, Brasil (1) | AF19: Itajai-SC - Vegetariana 🌱 Voluntária da causa animal 🐶💖😺 Maquiadora, Profª de Inglês. Mãe de 4🐶🐶🐶🐶 Lar Temporário do Bento 🐶 | AG19: https://instagram.com/melissagmenezes | AH19: Não contatada
A20: Itajaí | C20: @divulgaitajai | D20: DIVULGA ITAJAÍ | E20: Página local / guia | F20: Página/marca | G20: 15574 | H20: Micro (3k–30k) | I20: 0.0039 | J20: =IFERROR(INDEX('Como ler'!$B$20:$B$24,MATCH(H20,'Como ler'!$A$20:$A$24,0)),"") -> 0.025 | K20: =IF(OR(I20="",J20=""),"",I20/J20) -> 0.156 | L20: 68 | M20: 7.2 | N20: 228 | O20: =IF(OR(N20="",G20=0),"",N20/G20) -> 0.014639784 | P20: 0.36 | Q20: 3.2 | R20: 46290 | S20: =IF(R20="","",'Como ler'!$B$27-R20) -> 2 | T20: 0 | V20: Dicas locais | W20: Dicas locais, Educação e conhecimento | X20: Baixa | Y20: =ROUND(IF(K20="",0,MIN(40,40*K20/1.5))+IF(S20="",0,IF(S20<=7,20,IF(S20<=30,12,IF(S20<=90,5,0))))+IF(Q20="",0,MIN(15,Q20*5))+IF(O20="",0,MIN(15,O20*30))+IF(E20="Criador(a)",10,IF(E20="Especialista que cria conteúdo",6,4)),0) -> 44 | Z20: Community | AB20: Sim | AD20: Itajaí: bio, 5 post(s) marcados | AE20: Itajaí, Santa Catarina, Brasil (2), Alfa Bile (2), Molhes da Barra Itajaí (2), Disk Água Bebí (1) | AF20: 💙 Itajaí por @alfabile / ⚓️ Paisagens | Cotidiano | Arte / ✨ O olhar mais apaixonado pela nossa cidade / 👇 Wallpapers exclusivos e Dicas no Canal | AG20: https://instagram.com/divulgaitajai | AH20: Não contatada | AI20: Curtidas ocultas: engajamento calculado só com posts visíveis ou indisponível
A21: Itajaí | B21: Balneário Camboriú | C21: @solaynesantos | D21: ꜱᴏʟ - Influencer, Social Media & Videomaker | Itajaí | E21: Criador(a) | F21: Mulher | G21: 13517 | H21: Micro (3k–30k) | I21: 0.0056 | J21: =IFERROR(INDEX('Como ler'!$B$20:$B$24,MATCH(H21,'Como ler'!$A$20:$A$24,0)),"") -> 0.025 | K21: =IF(OR(I21="",J21=""),"",I21/J21) -> 0.224 | L21: 591 | M21: 17.8 | N21: 621 | O21: =IF(OR(N21="",G21=0),"",N21/G21) -> 0.045942147 | P21: 0.67 | Q21: 4 | R21: 46290 | S21: =IF(R21="","",'Como ler'!$B$27-R21) -> 2 | T21: 0 | V21: Gastronomia | W21: Gastronomia, Social mídia e conteúdo | X21: Alta | Y21: =ROUND(IF(K21="",0,MIN(40,40*K21/1.5))+IF(S21="",0,IF(S21<=7,20,IF(S21<=30,12,IF(S21<=90,5,0))))+IF(Q21="",0,MIN(15,Q21*5))+IF(O21="",0,MIN(15,O21*30))+IF(E21="Criador(a)",10,IF(E21="Especialista que cria conteúdo",6,4)),0) -> 52 | Z21: Digital creator | AC21: email | AD21: Itajaí: bio, 4 post(s) marcados; Balneário Camboriú: 2 post(s) marcados | AE21: Itajaí, Santa Catarina, Brasil (3), Balneário Camboriú (2), New Shoes Itajaí (1), Central Pádel Br (1) | AF21: 📱Influencer, Social Media & Videomaker / ✈️ Paulista em SC |📍Itajaí SC / 💡Criando conteúdo autêntico para sua marca! / 💌 [e-mail na bio] | AG21: https://instagram.com/solaynesantos | AH21: Não contatada
A22: Itajaí | C22: @brigadeiroealecrim | D22: Brigadeiro e Alecrim ® - Balneário Camboriú | E22: Criador(a) | F22: Mulher | G22: 12449 | H22: Micro (3k–30k) | I22: 0.0036 | J22: =IFERROR(INDEX('Como ler'!$B$20:$B$24,MATCH(H22,'Como ler'!$A$20:$A$24,0)),"") -> 0.025 | K22: =IF(OR(I22="",J22=""),"",I22/J22) -> 0.144 | L22: 45 | M22: 6.3 | N22: 480 | O22: =IF(OR(N22="",G22=0),"",N22/G22) -> 0.038557314 | P22: 0.7 | Q22: 1.4 | R22: 46278 | S22: =IF(R22="","",'Como ler'!$B$27-R22) -> 14 | T22: 0 | V22: Gastronomia | W22: Gastronomia | X22: Baixa | Y22: =ROUND(IF(K22="",0,MIN(40,40*K22/1.5))+IF(S22="",0,IF(S22<=7,20,IF(S22<=30,12,IF(S22<=90,5,0))))+IF(Q22="",0,MIN(15,Q22*5))+IF(O22="",0,MIN(15,O22*30))+IF(E22="Criador(a)",10,IF(E22="Especialista que cria conteúdo",6,4)),0) -> 34 | AB22: Sim | AD22: Itajaí: 7 post(s) marcados | AE22: Itajaí (7), Fazzenda Park Resort (1) | AF22: Depois de 10 anos entre panelas e doces, / resolvi experimentar o outro lado da mesa. / Aqui tem experiências que eu realmente acho que valem a pena! | AG22: https://instagram.com/brigadeiroealecrim | AH22: Não contatada
A23: Itajaí | C23: @eubarbaraabreu | D23: Bárbara Abreu | E23: Criador(a) | F23: Mulher | G23: 12418 | H23: Micro (3k–30k) | J23: =IFERROR(INDEX('Como ler'!$B$20:$B$24,MATCH(H23,'Como ler'!$A$20:$A$24,0)),"") -> 0.025 | K23: =IF(OR(I23="",J23=""),"",I23/J23) | M23: 11 | N23: 178 | O23: =IF(OR(N23="",G23=0),"",N23/G23) -> 0.014334031 | P23: 0.2 | Q23: 0.2 | R23: 46291 | S23: =IF(R23="","",'Como ler'!$B$27-R23) -> 1 | T23: 0 | V23: Beleza | W23: Beleza, Gastronomia | X23: Média | Y23: =ROUND(IF(K23="",0,MIN(40,40*K23/1.5))+IF(S23="",0,IF(S23<=7,20,IF(S23<=30,12,IF(S23<=90,5,0))))+IF(Q23="",0,MIN(15,Q23*5))+IF(O23="",0,MIN(15,O23*30))+IF(E23="Criador(a)",10,IF(E23="Especialista que cria conteúdo",6,4)),0) -> 31 | Z23: Digital creator | AC23: email | AD23: Itajaí: bio, 7 post(s) marcados | AE23: Itajaí (2), Itajaí -SC (2), Laviér Store Itajaí (1), Mercure Itajai Navegantes (1) | AF23: Bem-vinda(o)! / 👑 Miss Supranational Itajaí 2025 / 💌 [e-mail na bio] | AG23: https://instagram.com/eubarbaraabreu | AH23: Não contatada | AI23: Curtidas ocultas: engajamento calculado só com posts visíveis ou indisponível
A24: Itajaí | C24: @omelhordeitajai | E24: Página local / guia | F24: Página/marca | G24: 12104 | H24: Micro (3k–30k) | I24: 0.0051 | J24: =IFERROR(INDEX('Como ler'!$B$20:$B$24,MATCH(H24,'Como ler'!$A$20:$A$24,0)),"") -> 0.025 | K24: =IF(OR(I24="",J24=""),"",I24/J24) -> 0.204 | L24: 94 | M24: 1.8 | N24: 882 | O24: =IF(OR(N24="",G24=0),"",N24/G24) -> 0.072868473 | P24: 0.67 | Q24: 7.7 | R24: 46289 | S24: =IF(R24="","",'Como ler'!$B$27-R24) -> 3 | T24: 0 | V24: Viagem | W24: Viagem | X24: Baixa | Y24: =ROUND(IF(K24="",0,MIN(40,40*K24/1.5))+IF(S24="",0,IF(S24<=7,20,IF(S24<=30,12,IF(S24<=90,5,0))))+IF(Q24="",0,MIN(15,Q24*5))+IF(O24="",0,MIN(15,O24*30))+IF(E24="Criador(a)",10,IF(E24="Especialista que cria conteúdo",6,4)),0) -> 47 | AB24: Sim | AD24: Itajaí: bio | AF24: O destino começa aqui. / Belezas, sabores e experiências de Itajaí. / 🌊 Explore o melhor da cidade / Por: @itajaiconvention | AG24: https://instagram.com/omelhordeitajai | AH24: Não contatada
A25: Itajaí | C25: @lu.monaly | D25: Luciana Monaly | E25: Criador(a) | F25: Mulher | G25: 11743 | H25: Micro (3k–30k) | I25: 0.0063 | J25: =IFERROR(INDEX('Como ler'!$B$20:$B$24,MATCH(H25,'Como ler'!$A$20:$A$24,0)),"") -> 0.025 | K25: =IF(OR(I25="",J25=""),"",I25/J25) -> 0.252 | L25: 143 | M25: 4.8 | N25: 1539 | O25: =IF(OR(N25="",G25=0),"",N25/G25) -> 0.1310568 | P25: 0.91 | Q25: 0.9 | R25: 46291 | S25: =IF(R25="","",'Como ler'!$B$27-R25) -> 1 | T25: 0 | X25: Baixa | Y25: =ROUND(IF(K25="",0,MIN(40,40*K25/1.5))+IF(S25="",0,IF(S25<=7,20,IF(S25<=30,12,IF(S25<=90,5,0))))+IF(Q25="",0,MIN(15,Q25*5))+IF(O25="",0,MIN(15,O25*30))+IF(E25="Criador(a)",10,IF(E25="Especialista que cria conteúdo",6,4)),0) -> 45 | AD25: Itajaí: bio, 10 post(s) marcados | AE25: Itajaí -SC (6), Santa Catarina Itajai (4) | AF25: Itajaí SC / Modelo / Maquiadora- @monaly.makeup / Publicidade e Propaganda, Atriz por: @escolawolfmaya🎬 | AG25: https://instagram.com/lu.monaly | AH25: Não contatada
A26: Itajaí | C26: @cademinhascoisas | D26: Cadê Minhas Coisas? • Soluções em Organização | E26: Especialista que cria conteúdo | F26: Página/marca | G26: 10806 | H26: Micro (3k–30k) | I26: 0.0038 | J26: =IFERROR(INDEX('Como ler'!$B$20:$B$24,MATCH(H26,'Como ler'!$A$20:$A$24,0)),"") -> 0.025 | K26: =IF(OR(I26="",J26=""),"",I26/J26) -> 0.152 | L26: 50 | M26: 4.8 | N26: 376 | O26: =IF(OR(N26="",G26=0),"",N26/G26) -> 0.034795484 | P26: 0.78 | Q26: 2.7 | R26: 46245 | S26: =IF(R26="","",'Como ler'!$B$27-R26) -> 47 | T26: 0 | V26: Casa e organização | W26: Casa e organização, Família e maternidade | X26: Alta | Y26: =ROUND(IF(K26="",0,MIN(40,40*K26/1.5))+IF(S26="",0,IF(S26<=7,20,IF(S26<=30,12,IF(S26<=90,5,0))))+IF(Q26="",0,MIN(15,Q26*5))+IF(O26="",0,MIN(15,O26*30))+IF(E26="Criador(a)",10,IF(E26="Especialista que cria conteúdo",6,4)),0) -> 30 | AA26: Sim | AB26: Sim | AD26: Itajaí: bio | AF26: Desde 2013 transformando lares (e vidas!) 💖 / 📍 Curitiba | Itajaí | BC / Para orçamentos, clique no link abaixo 👇🏼 | AG26: https://instagram.com/cademinhascoisas | AH26: Não contatada
A27: Itajaí | C27: @bruna_alika | D27: Bruna Alika | E27: Criador(a) | F27: Mulher | G27: 10620 | H27: Micro (3k–30k) | I27: 0.0017 | J27: =IFERROR(INDEX('Como ler'!$B$20:$B$24,MATCH(H27,'Como ler'!$A$20:$A$24,0)),"") -> 0.025 | K27: =IF(OR(I27="",J27=""),"",I27/J27) -> 0.068 | L27: 23 | M27: 2.5 | N27: 414 | O27: =IF(OR(N27="",G27=0),"",N27/G27) -> 0.038983051 | P27: 1 | Q27: 3.5 | R27: 46292 | S27: =IF(R27="","",'Como ler'!$B$27-R27) -> 0 | T27: 0 | V27: Negócios e empreendedorismo | W27: Negócios e empreendedorismo, Família e maternidade, Gastronomia | X27: Alta | Y27: =ROUND(IF(K27="",0,MIN(40,40*K27/1.5))+IF(S27="",0,IF(S27<=7,20,IF(S27<=30,12,IF(S27<=90,5,0))))+IF(Q27="",0,MIN(15,Q27*5))+IF(O27="",0,MIN(15,O27*30))+IF(E27="Criador(a)",10,IF(E27="Especialista que cria conteúdo",6,4)),0) -> 48 | Z27: Digital creator | AB27: Sim | AD27: Itajaí: bio, 6 post(s) marcados | AE27: Itajaí (6), Arena Bombinhas (2) | AF27: Mulher Multifunções ligada no 220🤣 / + 15mil já dançaram comigo / 💻CEO @tourpexero / 💃@grupofloreser_ / ✨Dança @prefeituradeitajai / 🙏Mãe de 3 / Parceria | AG27: https://instagram.com/bruna_alika | AH27: Não contatada
A28: Itajaí | C28: @millycristt | D28: Emilly Cristine | StoryMaker e VideoMaker | E28: Especialista que cria conteúdo | F28: Mulher | G28: 10401 | H28: Micro (3k–30k) | I28: 0.0358 | J28: =IFERROR(INDEX('Como ler'!$B$20:$B$24,MATCH(H28,'Como ler'!$A$20:$A$24,0)),"") -> 0.025 | K28: =IF(OR(I28="",J28=""),"",I28/J28) -> 1.432 | L28: 994 | M28: 47.2 | N28: 4044 | O28: =IF(OR(N28="",G28=0),"",N28/G28) -> 0.38880877 | P28: 0.64 | Q28: 1.3 | R28: 46289 | S28: =IF(R28="","",'Como ler'!$B$27-R28) -> 3 | T28: 0 | V28: Social mídia e conteúdo | W28: Social mídia e conteúdo | X28: Alta | Y28: =ROUND(IF(K28="",0,MIN(40,40*K28/1.5))+IF(S28="",0,IF(S28<=7,20,IF(S28<=30,12,IF(S28<=90,5,0))))+IF(Q28="",0,MIN(15,Q28*5))+IF(O28="",0,MIN(15,O28*30))+IF(E28="Criador(a)",10,IF(E28="Especialista que cria conteúdo",6,4)),0) -> 82 | AB28: Sim | AD28: Itajaí: bio | AE28: Santa Catarina (1) | AF28: 🚀 | Transformo a sua ideia em um conteúdo impactante / 🤳🏼 | Fotografia • Vídeo • Real Time / 📍 | Itajaí e região / Eternize seu momento ⬇️ | AG28: https://instagram.com/millycristt | AH28: Não contatada
A29: Itajaí | C29: @thais_araujo.7 | D29: Thais | E29: Criador(a) | F29: Mulher | G29: 10330 | H29: Micro (3k–30k) | I29: 0.0251 | J29: =IFERROR(INDEX('Como ler'!$B$20:$B$24,MATCH(H29,'Como ler'!$A$20:$A$24,0)),"") -> 0.025 | K29: =IF(OR(I29="",J29=""),"",I29/J29) -> 1.004 | L29: 301 | M29: 9.9 | N29: 2782 | O29: =IF(OR(N29="",G29=0),"",N29/G29) -> 0.26931268 | P29: 0.43 | Q29: 0 | R29: 46267 | S29: =IF(R29="","",'Como ler'!$B$27-R29) -> 25 | T29: 0 | V29: UGC | W29: UGC, Dicas locais | X29: Alta | Y29: =ROUND(IF(K29="",0,MIN(40,40*K29/1.5))+IF(S29="",0,IF(S29<=7,20,IF(S29<=30,12,IF(S29<=90,5,0))))+IF(Q29="",0,MIN(15,Q29*5))+IF(O29="",0,MIN(15,O29*30))+IF(E29="Criador(a)",10,IF(E29="Especialista que cria conteúdo",6,4)),0) -> 57 | Z29: Digital creator | AB29: Sim | AD29: Itajaí: bio | AE29: Speedway Music Park (1), Chile (1), Lagoa Misteriosa (1) | AF29: 🌎 Lugares, sabores & aventuras / ✨ Transformando experiências em histórias / 📍 Itajaí • SC | UGC Creator / Bora viver essa experiência comigo? | AG29: https://instagram.com/thais_araujo.7 | AH29: Não contatada
A30: Itajaí | C30: @gabxmelo | D30: Gabi Melo 🌻 | E30: Criador(a) | F30: Mulher | G30: 9953 | H30: Micro (3k–30k) | I30: 0.0202 | J30: =IFERROR(INDEX('Como ler'!$B$20:$B$24,MATCH(H30,'Como ler'!$A$20:$A$24,0)),"") -> 0.025 | K30: =IF(OR(I30="",J30=""),"",I30/J30) -> 0.808 | L30: 255 | M30: 16.5 | O30: =IF(OR(N30="",G30=0),"",N30/G30) | P30: 0 | Q30: 0.3 | R30: 46258 | S30: =IF(R30="","",'Como ler'!$B$27-R30) -> 34 | T30: 0 | V30: Moda | W30: Moda | X30: Média | Y30: =ROUND(IF(K30="",0,MIN(40,40*K30/1.5))+IF(S30="",0,IF(S30<=7,20,IF(S30<=30,12,IF(S30<=90,5,0))))+IF(Q30="",0,MIN(15,Q30*5))+IF(O30="",0,MIN(15,O30*30))+IF(E30="Criador(a)",10,IF(E30="Especialista que cria conteúdo",6,4)),0) -> 38 | Z30: Personal blog | AD30: Itajaí: 3 post(s) marcados | AE30: Itajaí -SC (1), Praia Brava - Itajaí/SC (1), Santa Catarina Itajai (1) | AF30: SC 📍 / Comércio exterior 🛳️ / 🏳️‍🌈 | AG30: https://instagram.com/gabxmelo | AH30: Não contatada
A31: Itajaí | C31: @joanakathelen | D31: Joana Kathelen | E31: Criador(a) | F31: Mulher | G31: 9612 | H31: Micro (3k–30k) | I31: 0.0031 | J31: =IFERROR(INDEX('Como ler'!$B$20:$B$24,MATCH(H31,'Como ler'!$A$20:$A$24,0)),"") -> 0.025 | K31: =IF(OR(I31="",J31=""),"",I31/J31) -> 0.124 | L31: 28 | M31: 3.7 | N31: 336 | O31: =IF(OR(N31="",G31=0),"",N31/G31) -> 0.034956305 | P31: 0.5 | Q31: 0.2 | R31: 46263 | S31: =IF(R31="","",'Como ler'!$B$27-R31) -> 29 | T31: 0 | V31: Família e maternidade | W31: Família e maternidade | X31: Média | Y31: =ROUND(IF(K31="",0,MIN(40,40*K31/1.5))+IF(S31="",0,IF(S31<=7,20,IF(S31<=30,12,IF(S31<=90,5,0))))+IF(Q31="",0,MIN(15,Q31*5))+IF(O31="",0,MIN(15,O31*30))+IF(E31="Criador(a)",10,IF(E31="Especialista que cria conteúdo",6,4)),0) -> 27 | AD31: Itajaí: 11 post(s) marcados | AE31: Itajaí (8), Centro De Itajai Santa Catarina. (3) | AF31: 🌸 Mãe de dois príncipes / 💙@heitorbitencourt1 / 💚@henriquebitencourt2 / 💼 @serpa.log | AG31: https://instagram.com/joanakathelen | AH31: Não contatada
A32: Itajaí | C32: @n1kx_x | D32: Nicolly Machado - UGC Creator | E32: Criador(a) | F32: Mulher | G32: 9577 | H32: Micro (3k–30k) | I32: 0.0242 | J32: =IFERROR(INDEX('Como ler'!$B$20:$B$24,MATCH(H32,'Como ler'!$A$20:$A$24,0)),"") -> 0.025 | K32: =IF(OR(I32="",J32=""),"",I32/J32) -> 0.968 | L32: 258 | M32: 14.4 | O32: =IF(OR(N32="",G32=0),"",N32/G32) | P32: 0 | Q32: 0.1 | R32: 46253 | S32: =IF(R32="","",'Como ler'!$B$27-R32) -> 39 | T32: 0 | V32: UGC | W32: UGC, Casa e organização | X32: Alta | Y32: =ROUND(IF(K32="",0,MIN(40,40*K32/1.5))+IF(S32="",0,IF(S32<=7,20,IF(S32<=30,12,IF(S32<=90,5,0))))+IF(Q32="",0,MIN(15,Q32*5))+IF(O32="",0,MIN(15,O32*30))+IF(E32="Criador(a)",10,IF(E32="Especialista que cria conteúdo",6,4)),0) -> 41 | Z32: Public figure | AD32: Itajaí: 1 post(s) marcados | AE32: Goiânia, Brazil (1), Piscina Natural da Barra da Lagoa (1), Ilha da Magia - Floripa (1), Trancoso, Bahia, Brazil (1) | AF32: Design de interiores / 💼@campeche.joias | AG32: https://instagram.com/n1kx_x | AH32: Não contatada
A33: Itajaí | B33: Balneário Camboriú | C33: @itajaimilgr4u | D33: Itajai Mil Grau | E33: Página local / guia | F33: Página/marca | G33: 7887 | H33: Micro (3k–30k) | I33: 0.0075 | J33: =IFERROR(INDEX('Como ler'!$B$20:$B$24,MATCH(H33,'Como ler'!$A$20:$A$24,0)),"") -> 0.025 | K33: =IF(OR(I33="",J33=""),"",I33/J33) -> 0.3 | L33: 70 | M33: 5.8 | N33: 102 | O33: =IF(OR(N33="",G33=0),"",N33/G33) -> 0.012932674 | P33: 0.58 | Q33: 1.1 | R33: 46235 | S33: =IF(R33="","",'Como ler'!$B$27-R33) -> 57 | T33: 0 | V33: Moda | W33: Moda, Entretenimento e humor | X33: Baixa | Y33: =ROUND(IF(K33="",0,MIN(40,40*K33/1.5))+IF(S33="",0,IF(S33<=7,20,IF(S33<=30,12,IF(S33<=90,5,0))))+IF(Q33="",0,MIN(15,Q33*5))+IF(O33="",0,MIN(15,O33*30))+IF(E33="Criador(a)",10,IF(E33="Especialista que cria conteúdo",6,4)),0) -> 23 | Z33: Digital creator | AD33: Itajaí: bio, 6 post(s) marcados; Balneário Camboriú: 1 post(s) marcados | AE33: Itajaí -SC (4), Itajaí (1), Praia Do Atalaia - Itajaí (1), Balneário Camboriú - Praia (1) | AF33: Entretenimento, humor e curiosidades de Itajaí e Região / 🎯Conectando moradores,turistas e marcas locais / 💌Anuncie sua empresa com estilo e alcance real⚓ | AG33: https://instagram.com/itajaimilgr4u | AH33: Não contatada
A34: Itajaí | C34: @danielipickering | D34: Dani Pickering | E34: Criador(a) | F34: Mulher | G34: 7430 | H34: Micro (3k–30k) | I34: 0.0106 | J34: =IFERROR(INDEX('Como ler'!$B$20:$B$24,MATCH(H34,'Como ler'!$A$20:$A$24,0)),"") -> 0.025 | K34: =IF(OR(I34="",J34=""),"",I34/J34) -> 0.424 | L34: 82 | M34: 13.2 | N34: 653 | O34: =IF(OR(N34="",G34=0),"",N34/G34) -> 0.087886945 | P34: 0.75 | Q34: 0.3 | R34: 46292 | S34: =IF(R34="","",'Como ler'!$B$27-R34) -> 0 | T34: 0 | V34: Família e maternidade | W34: Família e maternidade, Fitness e wellness, Lifestyle, Negócios e empreendedorismo | X34: Alta | Y34: =ROUND(IF(K34="",0,MIN(40,40*K34/1.5))+IF(S34="",0,IF(S34<=7,20,IF(S34<=30,12,IF(S34<=90,5,0))))+IF(Q34="",0,MIN(15,Q34*5))+IF(O34="",0,MIN(15,O34*30))+IF(E34="Criador(a)",10,IF(E34="Especialista que cria conteúdo",6,4)),0) -> 45 | AD34: Itajaí: 4 post(s) marcados | AE34: Itajaí (3), Itajaí -SC (1), Greenvalley (1) | AF34: Mãe da Kali 💓 / Movimento, trabalho e vida real ✨ / Marketing do Grupo Health Brasil / @healthycann @healthimporter / @healthimporter @nexpurepharma | AG34: https://instagram.com/danielipickering | AH34: Não contatada
A35: Itajaí | C35: @ana_paula_videomaker | D35: VIDEOMAKER MOBILE | ITAJAÍ | E35: Especialista que cria conteúdo | F35: Mulher | G35: 7365 | H35: Micro (3k–30k) | I35: 0.0036 | J35: =IFERROR(INDEX('Como ler'!$B$20:$B$24,MATCH(H35,'Como ler'!$A$20:$A$24,0)),"") -> 0.025 | K35: =IF(OR(I35="",J35=""),"",I35/J35) -> 0.144 | L35: 41 | M35: 4.9 | N35: 228 | O35: =IF(OR(N35="",G35=0),"",N35/G35) -> 0.03095723 | P35: 1 | Q35: 0.4 | R35: 46099 | S35: =IF(R35="","",'Como ler'!$B$27-R35) -> 193 | T35: 5 | U35: @ericaalme_, @lucasfelipexavier, @mariana_talamini, @esquina_doacairs | V35: Social mídia e conteúdo | W35: Social mídia e conteúdo, Relacionamento | X35: Alta | Y35: =ROUND(IF(K35="",0,MIN(40,40*K35/1.5))+IF(S35="",0,IF(S35<=7,20,IF(S35<=30,12,IF(S35<=90,5,0))))+IF(Q35="",0,MIN(15,Q35*5))+IF(O35="",0,MIN(15,O35*30))+IF(E35="Criador(a)",10,IF(E35="Especialista que cria conteúdo",6,4)),0) -> 13 | Z35: Reel creator | AD35: Itajaí: bio | AE35: Itaipava Club Residence (1) | AF35: 🎥 Videomaker Mobile | Itajaí-SC / 🎬 Transformo momentos em memória pelo celular 📲 ✨ Capto emoções reais em vídeo / 📱 Acesse o link e veja meu portfólio ⬇️ | AG35: https://instagram.com/ana_paula_videomaker | AH35: Não contatada
A36: Itajaí | C36: @marcelabontorin | D36: Marcela Bontorin | Estrategista de Imagem e Mentora | E36: Especialista que cria conteúdo | F36: Mulher | G36: 6620 | H36: Micro (3k–30k) | I36: 0.0115 | J36: =IFERROR(INDEX('Como ler'!$B$20:$B$24,MATCH(H36,'Como ler'!$A$20:$A$24,0)),"") -> 0.025 | K36: =IF(OR(I36="",J36=""),"",I36/J36) -> 0.46 | L36: 61 | M36: 18.5 | N36: 961 | O36: =IF(OR(N36="",G36=0),"",N36/G36) -> 0.14516616 | P36: 0.27 | Q36: 0.1 | R36: 46289 | S36: =IF(R36="","",'Como ler'!$B$27-R36) -> 3 | T36: 0 | V36: Negócios e empreendedorismo | W36: Negócios e empreendedorismo, Social mídia e conteúdo, Moda | X36: Alta | Y36: =ROUND(IF(K36="",0,MIN(40,40*K36/1.5))+IF(S36="",0,IF(S36<=7,20,IF(S36<=30,12,IF(S36<=90,5,0))))+IF(Q36="",0,MIN(15,Q36*5))+IF(O36="",0,MIN(15,O36*30))+IF(E36="Criador(a)",10,IF(E36="Especialista que cria conteúdo",6,4)),0) -> 43 | Z36: None | AA36: Sim | AB36: Sim | AD36: Itajaí: 2 post(s) marcados | AE36: Estaleiro Guest House (1), Luvcoffee (1), Itajaí -SC (1), Santa Catarina Itajai (1) | AF36: “Autoridade não se veste, se constrói” / Empreendedora | Mentora | Palestrante / @ecossdosucesso @arlinkinternet @moda_circula_ @literariasdovale | AG36: https://instagram.com/marcelabontorin | AH36: Não contatada
A37: Itajaí | C37: @tonsdeana | D37: Ana Antonelo | Comunicadora de Moda | E37: Criador(a) | F37: Mulher | G37: 6134 | H37: Micro (3k–30k) | J37: =IFERROR(INDEX('Como ler'!$B$20:$B$24,MATCH(H37,'Como ler'!$A$20:$A$24,0)),"") -> 0.025 | K37: =IF(OR(I37="",J37=""),"",I37/J37) | M37: 19 | N37: 388 | O37: =IF(OR(N37="",G37=0),"",N37/G37) -> 0.063253994 | P37: 0.7 | Q37: 10.5 | R37: 46292 | S37: =IF(R37="","",'Como ler'!$B$27-R37) -> 0 | T37: 0 | V37: Moda | W37: Moda | X37: Média | Y37: =ROUND(IF(K37="",0,MIN(40,40*K37/1.5))+IF(S37="",0,IF(S37<=7,20,IF(S37<=30,12,IF(S37<=90,5,0))))+IF(Q37="",0,MIN(15,Q37*5))+IF(O37="",0,MIN(15,O37*30))+IF(E37="Criador(a)",10,IF(E37="Especialista que cria conteúdo",6,4)),0) -> 47 | Z37: None | AB37: Sim | AD37: Itajaí: 9 post(s) marcados | AE37: Itajaí, Santa Catarina, Brasil (8), Joinville Santa Catarina (1), Mercado Velho Itajaí (1) | AF37: Hoje eu acordei querendo te irritar, / será que eu consigo? 👀 / Aqui tem moda com borogodó & muito brechó! ✨ / Crio conteúdos autênticos para sua marca 🫵🏻 | AG37: https://instagram.com/tonsdeana | AH37: Não contatada | AI37: Curtidas ocultas: engajamento calculado só com posts visíveis ou indisponível
A38: Itajaí | C38: @brunasamanthas | D38: Bruna Samantha | Corretora de Imóveis | E38: Especialista que cria conteúdo | F38: Mulher | G38: 5771 | H38: Micro (3k–30k) | I38: 0.0113 | J38: =IFERROR(INDEX('Como ler'!$B$20:$B$24,MATCH(H38,'Como ler'!$A$20:$A$24,0)),"") -> 0.025 | K38: =IF(OR(I38="",J38=""),"",I38/J38) -> 0.452 | L38: 58 | M38: 7.3 | N38: 392 | O38: =IF(OR(N38="",G38=0),"",N38/G38) -> 0.067925836 | P38: 0.83 | Q38: 0.4 | R38: 46265 | S38: =IF(R38="","",'Como ler'!$B$27-R38) -> 27 | T38: 0 | V38: Finanças | W38: Finanças, Viagem, Negócios e empreendedorismo, Família e maternidade | X38: Alta | Y38: =ROUND(IF(K38="",0,MIN(40,40*K38/1.5))+IF(S38="",0,IF(S38<=7,20,IF(S38<=30,12,IF(S38<=90,5,0))))+IF(Q38="",0,MIN(15,Q38*5))+IF(O38="",0,MIN(15,O38*30))+IF(E38="Criador(a)",10,IF(E38="Especialista que cria conteúdo",6,4)),0) -> 34 | Z38: Digital creator | AB38: Sim | AD38: Itajaí: bio, 6 post(s) marcados | AE38: Praia Brava - Itajaí/SC (6) | AF38: Imóveis únicos, localizações desejadas. / Investimentos inteligentes. / Corretora Associada @jeancarloexclusive / 📍Itajaí | Praia Brava | BC / CRECI SC 68926F | AG38: https://instagram.com/brunasamanthas | AH38: Não contatada
A39: Itajaí | B39: Itapema | C39: @andreza.marinho_22 | D39: Andreza Marinho | Atleta | E39: Criador(a) | F39: Mulher | G39: 5648 | H39: Micro (3k–30k) | I39: 0.0282 | J39: =IFERROR(INDEX('Como ler'!$B$20:$B$24,MATCH(H39,'Como ler'!$A$20:$A$24,0)),"") -> 0.025 | K39: =IF(OR(I39="",J39=""),"",I39/J39) -> 1.128 | L39: 148 | M39: 6.8 | N39: 1382 | O39: =IF(OR(N39="",G39=0),"",N39/G39) -> 0.24468839 | P39: 0.5 | Q39: 0.6 | R39: 46290 | S39: =IF(R39="","",'Como ler'!$B$27-R39) -> 2 | T39: 0 | V39: Fitness e wellness | W39: Fitness e wellness | X39: Baixa | Y39: =ROUND(IF(K39="",0,MIN(40,40*K39/1.5))+IF(S39="",0,IF(S39<=7,20,IF(S39<=30,12,IF(S39<=90,5,0))))+IF(Q39="",0,MIN(15,Q39*5))+IF(O39="",0,MIN(15,O39*30))+IF(E39="Criador(a)",10,IF(E39="Especialista que cria conteúdo",6,4)),0) -> 70 | Z39: Personal blog | AD39: Itajaí: bio; Itapema: 1 post(s) marcados | AE39: Hard Rock Cafe Itapema (1) | AF39: 🏃🏻‍♀️ Corredora | Itajaí-SC / 🏅 9 pódios em 1 ano / 📈 Evolução, disciplina & constância / 🧸 Respeita o pace fofo / 🤝 Parcerias & patrocínios | AG39: https://instagram.com/andreza.marinho_22 | AH39: Não contatada
A40: Itajaí | B40: Itapema | C40: @brunoleon.blm | D40: Bruno Leon | Corrida e Vida Real | E40: Criador(a) | F40: Homem | G40: 4593 | H40: Micro (3k–30k) | I40: 0.047 | J40: =IFERROR(INDEX('Como ler'!$B$20:$B$24,MATCH(H40,'Como ler'!$A$20:$A$24,0)),"") -> 0.025 | K40: =IF(OR(I40="",J40=""),"",I40/J40) -> 1.88 | L40: 285 | M40: 40.6 | N40: 2529 | O40: =IF(OR(N40="",G40=0),"",N40/G40) -> 0.55062051 | P40: 0.67 | Q40: 2.3 | R40: 46291 | S40: =IF(R40="","",'Como ler'!$B$27-R40) -> 1 | T40: 0 | V40: Fitness e wellness | W40: Fitness e wellness, Lifestyle, Negócios e empreendedorismo, Família e maternidade | X40: Alta | Y40: =ROUND(IF(K40="",0,MIN(40,40*K40/1.5))+IF(S40="",0,IF(S40<=7,20,IF(S40<=30,12,IF(S40<=90,5,0))))+IF(Q40="",0,MIN(15,Q40*5))+IF(O40="",0,MIN(15,O40*30))+IF(E40="Criador(a)",10,IF(E40="Especialista que cria conteúdo",6,4)),0) -> 97 | Z40: Athlete | AB40: Sim | AD40: Itajaí: 2 post(s) marcados; Itapema: 1 post(s) marcados | AE40: Pista De Atletismo De Itajai (2), Itapema, Brazil (1), Beira Mar.. Floripa.. (1), Maratona Internacional de Floripa (1) | AF40: ✞ JESUS ✞ / 👶🏻 Pai da Milena - 610g 🎀 / 🏅MARATONISTA - 02:49:28 / CEO 🏃🏻 @assessoria.leon / 💍 @luujohann / 💼 @donaruiva.pijamas / Faça parte da ASSESSORIA ⬇️ | AG40: https://instagram.com/brunoleon.blm | AH40: Não contatada
...

Sheet Itajaí
A1: Cidade principal | B1: Também atua em | C1: Perfil | D1: Nome | E1: Tipo | F1: Criador(a) | G1: Seguidores | H1: Faixa | I1: Engajamento | J1: Engaj. de referência | K1: Engaj. vs referência | L1: Média de curtidas | M1: Média de comentários | N1: Views medianas (reels) | O1: Views/seguidores | P1: % vídeos | Q1: Posts/semana | R1: Último post | S1: Dias sem postar | T1: Publis (de 12) | U1: Marcas em publis | V1: Nicho principal | W1: Nichos | X1: Fit CRIA | Y1: Score (0-100) | Z1: Categoria no IG | AA1: Verificado | AB1: Link na bio | AC1: Canal de contato | AD1: Como confirmei a cidade | AE1: Locais marcados | AF1: Bio | AG1: Link | AH1: Status | AI1: Observações
